Workbook

Sheet Read Me
A1: GreenThreads Operations — Denver Launch Supplier Risk
A3: HW#3 Data Intelligence Project — combined supporting analysis
A4: Company: GreenThreads (sustainable apparel) | Function: Operations | Denver opening: October 12, 2026
A5: Function goal (HW#1): get the four launch products onto the Denver sales floor on time.
A6: Analysis date (As_of_Date): August 12, 2026
A8: Tabs
A9: Data Dictionary — every field defined and classified before analysis, with its quality rule.
A10: Cleaning & Validation — every check run, its result, treatment, and business reason.
A11: Supplier Reliability — frequency (% late) and severity (avg days late) plus active overdue exposure.
A12: Launch Risk — the four launch SKUs mapped to supplier reliability, retail value, and carton status.
A13: Choice Set — three options with trade-offs and the recommendation.
A14: Shipments Data / SKU Catalog — raw source data the analysis tabs reference by formula.
... A29: contract terms. AI calculates and flags; a human reviews every trigger and makes the final decision.

Sheet Data Dictionary
A1: Data Dictionary
A2: Field meanings confirmed before analysis. Classification separates inputs, calculated outcomes, and validation fields.
A4: Dataset | B4: Field | C4: Business definition | D4: Type | E4: Classification | F4: Used for | G4: Quality rule
A5: Shipments | B5: PO_Number | C5: Unique purchase-order identifier. | D5: Text | E5: Identifier | F5: Row traceability | G5: Required; unique; PO-#### format
A6: Shipments | B6: SKU | C6: GreenThreads stock-keeping unit identifier. | D6: Text | E6: Identifier | F6: Join to catalog | G6: Required; maps to one product
A7: Shipments | B7: Product_Name | C7: Product associated with the SKU. | D7: Text | E7: Descriptor | F7: Product-level analysis | G7: Must agree with SKU catalog
A8: Shipments | B8: Supplier | C8: Vendor responsible for the shipment. | D8: Text | E8: Dimension | F8: Supplier reliability | G8: Must map to one country; one spelling
A9: Shipments | B9: Supplier_Country | C9: Country associated with the supplier. | D9: Text | E9: Dimension | F9: Geographic exposure | G9: Must agree with catalog
A10: Shipments | B10: Destination_Store | C10: Store receiving the purchase order. | D10: Text | E10: Dimension | F10: Destination analysis | G10: Required
A11: Shipments | B11: Order_Date | C11: Date GreenThreads placed the order. | D11: Date | E11: Input | F11: Lead-time validation | G11: Must be <= promised date
A12: Shipments | B12: Promised_Date | C12: Supplier-planned receipt date. | D12: Date | E12: Input | F12: On-time calculation | G12: Must be >= order date
A13: Shipments | B13: Actual_Receipt_Date | C13: Actual receipt date; legitimately blank while in transit. | D13: Date | E13: Outcome | F13: Delay calculation | G13: Required only when Received
A14: Shipments | B14: Status | C14: Shipment state: Received or In transit. | D14: Text | E14: Status | F14: Population selection | G14: Must agree with receipt-date presence
A15: Shipments | B15: Days_Late | C15: Completed-shipment delay: actual minus promised. Blank in transit. | D15: Number | E15: Calculated outcome | F15: Reliability severity | G15: Recalculate and match
... A29: Catalog | B29: Denver_Opening_Buy_Units | C29: Units bought for the Denver opening. | D29: Integer | E29: Input | F29: Launch exposure | G29: Must meet MOQ

Sheet Cleaning & Validation
A1: Cleaning & Validation
A2: Issues documented transparently. Valid in-transit blanks preserved as unknowns rather than zeroed; no source values silently changed.
A4: # | B4: Check | C4: Result | D4: Status | E4: Treatment | F4: Business reason
A5: 1 | B5: Shipment row count | C5: 96 rows present | D5: Pass | E5: Retained | F5: Complete analysis population
A6: 2 | B6: Duplicate PO numbers | C6: 0 duplicates (PO-4400 to PO-4495) | D6: Pass | E6: No removal needed | F6: Avoids double counting
A7: 3 | B7: Required shipment fields | C7: 0 missing required fields | D7: Pass | E7: No correction needed | F7: Identifiers and inputs complete
A8: 4 | B8: Date logic (order <= promised) | C8: 0 invalid date sequences | D8: Pass | E8: No correction needed | F8: Prevents negative lead-time errors
A9: 5 | B9: Status / receipt consistency | C9: 0 conflicts | D9: Pass | E9: No correction needed | F9: Status controls eligible calculations
A10: 6 | B10: Line-cost reconciliation | C10: 0 mismatches (Units x Unit_Cost) | D10: Pass | E10: No correction needed | F10: Protects cost totals
A11: 7 | B11: Days_Late recalculation | C11: 0 mismatches across 80 received rows | D11: Pass | E11: No correction needed | F11: Verifies AI-reported delay math
A12: 8 | B12: Cross-file catalog mapping | C12: 0 mapping or economics mismatches | D12: Pass | E12: No correction needed | F12: SKU, supplier, country, cost reconcile
A13: 9 | B13: Valid in-transit blanks | C13: 32 blanks across 16 rows | D13: Expected | E13: Preserved as blank; measured against As_of_Date instead | F13: An unknown receipt is not an on-time receipt
A14: 10 | B14: Supplier name consistency | C14: 4 suppliers, 1 spelling each in this file version | D14: Pass (watch) | E14: Normalization step retained in the pipeline | F14: An earlier export split Andes Knitworks across two spellings, which would understate its order volume
A15: 11 | B15: Launch carton multiples | C15: 3 of 4 launch buys are not whole cartons (Hoodie 70.8, Tee 66.7, Joggers 59.4) | D15: Needs verification | E15: Escalated for quantity confirmation; source not changed | F15: Avoids unsupported data edits and receiving disputes
... A17: 13 | B17: 'On-time' definition | C17: 0 early deliveries; 23 arrived exactly on the promised day | D17: Documented | E17: Report % late and avg days late together | F17: On-time rate alone flatters suppliers that are never early

Sheet Shipments Data
A1: PO_Number | B1: SKU | C1: Product_Name | D1: Supplier | E1: Supplier_Country | F1: Destination_Store | G1: Order_Date | H1: Promised_Date | I1: Actual_Receipt_Date | J1: Status | K1: Days_Late | L1: Units | M1: Unit_Cost | N1: Line_Cost
A2: PO-4400 | B2: GT-CHN-07 | C2: Slim Chino | D2: Mekong Textile Co. | E2: Vietnam | F2: Boise | G2: 46064 | H2: 46124 | I2: 46132 | J2: Received | K2: 8 | L2: 400 | M2: 26 | N2: 10400
A3: PO-4401 | B3: GT-JKT-08 | C3: Recycled Denim Jacket | D3: Andes Knitworks | E3: Colombia | F3: Spokane | G3: 46007 | H3: 46037 | I3: 46037 | J3: Received | K3: 0 | L3: 600 | M3: 46 | N3: 27600
A4: PO-4402 | B4: GT-JOG-03 | C4: Bamboo Joggers | D4: Song Hong Apparel | E4: Vietnam | F4: Portland-Division | G4: 46162 | H4: 46227 | J4: In transit | L4: 600 | M4: 30 | N4: 18000
A5: PO-4403 | B5: GT-JOG-03 | C5: Bamboo Joggers | D5: Song Hong Apparel | E5: Vietnam | F5: Tacoma | G5: 46027 | H5: 46092 | I5: 46105 | J5: Received | K5: 13 | L5: 200 | M5: 30 | N5: 6000
A6: PO-4404 | B6: GT-TNK-06 | C6: Organic Tank Top | D6: Delta Organics | E6: India | F6: Eugene | G6: 46186 | H6: 46231 | J6: In transit | L6: 250 | M6: 11 | N6: 2750
A7: PO-4405 | B7: GT-POL-05 | C7: Performance Polo | D7: Delta Organics | E7: India | F7: Tacoma | G7: 46102 | H7: 46147 | I7: 46147 | J7: Received | K7: 0 | L7: 150 | M7: 19.5 | N7: 2925
A8: PO-4406 | B8: GT-POL-05 | C8: Performance Polo | D8: Delta Organics | E8: India | F8: Spokane | G8: 46130 | H8: 46175 | I8: 46175 | J8: Received | K8: 0 | L8: 500 | M8: 19.5 | N8: 9750
A9: PO-4407 | B9: GT-JOG-03 | C9: Bamboo Joggers | D9: Song Hong Apparel | E9: Vietnam | F9: Seattle-Cap Hill | G9: 46111 | H9: 46176 | I9: 46187 | J9: Received | K9: 11 | L9: 250 | M9: 30 | N9: 7500
A10: PO-4408 | B10: GT-JKT-08 | C10: Recycled Denim Jacket | D10: Andes Knitworks | E10: Colombia | F10: Austin-South Congress | G10: 46109 | H10: 46139 | I10: 46140 | J10: Received | K10: 1 | L10: 500 | M10: 46 | N10: 23000
A11: PO-4409 | B11: GT-SHT-02 | C11: Active Shorts | D11: Mekong Textile Co. | E11: Vietnam | F11: Tacoma | G11: 46169 | H11: 46229 | J11: In transit | L11: 500 | M11: 22 | N11: 11000
A12: PO-4410 | B12: GT-JOG-03 | C12: Bamboo Joggers | D12: Song Hong Apparel | E12: Vietnam | F12: Salt Lake City | G12: 46059 | H12: 46124 | I12: 46137 | J12: Received | K12: 13 | L12: 250 | M12: 30 | N12: 7500
A13: PO-4411 | B13: GT-TNK-06 | C13: Organic Tank Top | D13: Delta Organics | E13: India | F13: Spokane | G13: 46017 | H13: 46062 | I13: 46063 | J13: Received | K13: 1 | L13: 600 | M13: 11 | N13: 6600
A14: PO-4412 | B14: GT-SHT-02 | C14: Active Shorts | D14: Mekong Textile Co. | E14: Vietnam | F14: Bend | G14: 46101 | H14: 46161 | I14: 46173 | J14: Received | K14: 12 | L14: 400 | M14: 22 | N14: 8800
A15: PO-4413 | B15: GT-POL-05 | C15: Performance Polo | D15: Delta Organics | E15: India | F15: Boulder | G15: 46165 | H15: 46210 | I15: 46210 | J15: Received | K15: 0 | L15: 400 | M15: 19.5 | N15: 7800
A16: PO-4414 | B16: GT-JOG-03 | C16: Bamboo Joggers | D16: Song Hong Apparel | E16: Vietnam | F16: Boise | G16: 46063 | H16: 46128 | I16: 46139 | J16: Received | K16: 11 | L16: 150 | M16: 30 | N16: 4500
A17: PO-4415 | B17: GT-SHT-02 | C17: Active Shorts | D17: Mekong Textile Co. | E17: Vietnam | F17: Boulder | G17: 46122 | H17: 46182 | I17: 46188 | J17: Received | K17: 6 | L17: 300 | M17: 22 | N17: 6600
A18: PO-4416 | B18: GT-CHN-07 | C18: Slim Chino | D18: Mekong Textile Co. | E18: Vietnam | F18: Tacoma | G18: 46118 | H18: 46178 | I18: 46183 | J18: Received | K18: 5 | L18: 250 | M18: 26 | N18: 6500
A19: PO-4417 | B19: GT-JOG-03 | C19: Bamboo Joggers | D19: Song Hong Apparel | E19: Vietnam | F19: Seattle-Ballard | G19: 46007 | H19: 46072 | I19: 46079 | J19: Received | K19: 7 | L19: 200 | M19: 30 | N19: 6000
A20: PO-4418 | B20: GT-JOG-03 | C20: Bamboo Joggers | D20: Song Hong Apparel | E20: Vietnam | F20: Seattle-Cap Hill | G20: 46029 | H20: 46094 | I20: 46113 | J20: Received | K20: 19 | L20: 600 | M20: 30 | N20: 18000
A21: PO-4419 | B21: GT-JOG-03 | C21: Bamboo Joggers | D21: Song Hong Apparel | E21: Vietnam | F21: Bend | G21: 46187 | H21: 46252 | J21: In transit | L21: 250 | M21: 30 | N21: 7500
A22: PO-4420 | B22: GT-HOD-04 | C22: EcoFleece Hoodie | D22: Andes Knitworks | E22: Colombia | F22: Boulder | G22: 46102 | H22: 46132 | I22: 46132 | J22: Received | K22: 0 | L22: 400 | M22: 38 | N22: 15200
A23: PO-4421 | B23: GT-CHN-07 | C23: Slim Chino | D23: Mekong Textile Co. | E23: Vietnam | F23: Seattle-Cap Hill | G23: 46178 | H23: 46238 | J23: In transit | L23: 400 | M23: 26 | N23: 10400
A24: PO-4422 | B24: GT-SHT-02 | C24: Active Shorts | D24: Mekong Textile Co. | E24: Vietnam | F24: Boise | G24: 46142 | H24: 46202 | I24: 46207 | J24: Received | K24: 5 | L24: 400 | M24: 22 | N24: 8800
A25: PO-4423 | B25: GT-HOD-04 | C25: EcoFleece Hoodie | D25: Andes Knitworks | E25: Colombia | F25: Boulder | G25: 46018 | H25: 46048 | I25: 46048 | J25: Received | K25: 0 | L25: 250 | M25: 38 | N25: 9500
A26: PO-4424 | B26: GT-JKT-08 | C26: Recycled Denim Jacket | D26: Andes Knitworks | E26: Colombia | F26: Spokane | G26: 46065 | H26: 46095 | I26: 46096 | J26: Received | K26: 1 | L26: 200 | M26: 46 | N26: 9200
A27: PO-4425 | B27: GT-CHN-07 | C27: Slim Chino | D27: Mekong Textile Co. | E27: Vietnam | F27: Bend | G27: 46035 | H27: 46095 | I27: 46101 | J27: Received | K27: 6 | L27: 200 | M27: 26 | N27: 5200
A28: PO-4426 | B28: GT-HOD-04 | C28: EcoFleece Hoodie | D28: Andes Knitworks | E28: Colombia | F28: Spokane | G28: 46142 | H28: 46172 | I28: 46173 | J28: Received | K28: 1 | L28: 150 | M28: 38 | N28: 5700
A29: PO-4427 | B29: GT-HOD-04 | C29: EcoFleece Hoodie | D29: Andes Knitworks | E29: Colombia | F29: Seattle-Cap Hill | G29: 46091 | H29: 46121 | I29: 46122 | J29: Received | K29: 1 | L29: 200 | M29: 38 | N29: 7600
A30: PO-4428 | B30: GT-HOD-04 | C30: EcoFleece Hoodie | D30: Andes Knitworks | E30: Colombia | F30: Tacoma | G30: 46081 | H30: 46111 | I30: 46112 | J30: Received | K30: 1 | L30: 250 | M30: 38 | N30: 9500
A31: PO-4429 | B31: GT-POL-05 | C31: Performance Polo | D31: Delta Organics | E31: India | F31: Portland-Pearl | G31: 46170 | H31: 46215 | I31: 46217 | J31: Received | K31: 2 | L31: 400 | M31: 19.5 | N31: 7800
A32: PO-4430 | B32: GT-JKT-08 | C32: Recycled Denim Jacket | D32: Andes Knitworks | E32: Colombia | F32: Seattle-Cap Hill | G32: 46032 | H32: 46062 | I32: 46062 | J32: Received | K32: 0 | L32: 300 | M32: 46 | N32: 13800
A33: PO-4431 | B33: GT-TEE-01 | C33: Classic Tee | D33: Delta Organics | E33: India | F33: Boise | G33: 46161 | H33: 46206 | I33: 46207 | J33: Received | K33: 1 | L33: 500 | M33: 14.25 | N33: 7125
A34: PO-4432 | B34: GT-JOG-03 | C34: Bamboo Joggers | D34: Song Hong Apparel | E34: Vietnam | F34: Portland-Division | G34: 46087 | H34: 46152 | I34: 46169 | J34: Received | K34: 17 | L34: 500 | M34: 30 | N34: 15000
A35: PO-4433 | B35: GT-SHT-02 | C35: Active Shorts | D35: Mekong Textile Co. | E35: Vietnam | F35: Austin-South Congress | G35: 46167 | H35: 46227 | J35: In transit | L35: 200 | M35: 22 | N35: 4400
A36: PO-4434 | B36: GT-HOD-04 | C36: EcoFleece Hoodie | D36: Andes Knitworks | E36: Colombia | F36: Eugene | G36: 46057 | H36: 46087 | I36: 46087 | J36: Received | K36: 0 | L36: 250 | M36: 38 | N36: 9500
A37: PO-4435 | B37: GT-JOG-03 | C37: Bamboo Joggers | D37: Song Hong Apparel | E37: Vietnam | F37: Eugene | G37: 46054 | H37: 46119 | I37: 46130 | J37: Received | K37: 11 | L37: 400 | M37: 30 | N37: 12000
A38: PO-4436 | B38: GT-POL-05 | C38: Performance Polo | D38: Delta Organics | E38: India | F38: Boise | G38: 46057 | H38: 46102 | I38: 46102 | J38: Received | K38: 0 | L38: 250 | M38: 19.5 | N38: 4875
A39: PO-4437 | B39: GT-TEE-01 | C39: Classic Tee | D39: Delta Organics | E39: India | F39: Austin-South Congress | G39: 46079 | H39: 46124 | I39: 46124 | J39: Received | K39: 0 | L39: 250 | M39: 14.25 | N39: 3562.5
A40: PO-4438 | B40: GT-CHN-07 | C40: Slim Chino | D40: Mekong Textile Co. | E40: Vietnam | F40: Spokane | G40: 46102 | H40: 46162 | I40: 46174 | J40: Received | K40: 12 | L40: 250 | M40: 26 | N40: 6500
...

Sheet SKU Catalog
A1: SKU | B1: Product_Name | C1: Category | D1: Material | E1: Sustainability_Cert | F1: Supplier | G1: Supplier_Country | H1: Lead_Time_Days | I1: MOQ_Units | J1: Wholesale_Cost | K1: MSRP | L1: Unit_Margin | M1: Margin_Pct | N1: Units_Per_Carton | O1: In_Denver_Launch | P1: Denver_Opening_Buy_Units | Q1: Opening_Buy_Cost | R1: Opening_Buy_Retail_Value | S1: Order_By_Date | T1: Days_Until_Order_Deadline | U1: Notes
A2: GT-HOD-04 | B2: EcoFleece Hoodie | C2: Outerwear | D2: Recycled fleece | E2: GRS | F2: Andes Knitworks | G2: Colombia | H2: 30 | I2: 200 | J2: 38 | K2: 98 | L2: 60 | M2: 0.612 | N2: 12 | O2: Y | P2: 850 | Q2: 32300 | R2: 83300 | S2: 46277 | T2: 60
A3: GT-JKT-08 | B3: Recycled Denim Jacket | C3: Outerwear | D3: Recycled denim | E3: GRS | F3: Andes Knitworks | G3: Colombia | H3: 35 | I3: 150 | J3: 46 | K3: 118 | L3: 72 | M3: 0.61 | N3: 8 | O3: N | P3: 0 | Q3: 0 | R3: 0 | U3: In GreenThreads catalog; stocked at other stores. Not in the Denver launch assortment.
A4: GT-TEE-01 | B4: Classic Tee | C4: Tops | D4: Organic cotton | E4: GOTS | F4: Delta Organics | G4: India | H4: 45 | I4: 500 | J4: 14.25 | K4: 38 | L4: 23.75 | M4: 0.625 | N4: 24 | O4: Y | P4: 1600 | Q4: 22800 | R4: 60800 | S4: 46262 | T4: 45
A5: GT-POL-05 | B5: Performance Polo | C5: Tops | D5: Recycled pique | E5: GRS | F5: Delta Organics | G5: India | H5: 45 | I5: 400 | J5: 19.5 | K5: 52 | L5: 32.5 | M5: 0.625 | N5: 24 | O5: N | P5: 0 | Q5: 0 | R5: 0 | U5: In GreenThreads catalog; stocked at other stores. Not in the Denver launch assortment.
A6: GT-TNK-06 | B6: Organic Tank Top | C6: Tops | D6: Organic cotton | E6: GOTS | F6: Delta Organics | G6: India | H6: 40 | I6: 500 | J6: 11 | K6: 30 | L6: 19 | M6: 0.633 | N6: 30 | O6: N | P6: 0 | Q6: 0 | R6: 0 | U6: In GreenThreads catalog; stocked at other stores. Not in the Denver launch assortment.
A7: GT-SHT-02 | B7: Active Shorts | C7: Bottoms | D7: Recycled polyester | E7: GRS | F7: Mekong Textile Co. | G7: Vietnam | H7: 60 | I7: 300 | J7: 22 | K7: 58 | L7: 36 | M7: 0.621 | N7: 20 | O7: Y | P7: 1200 | Q7: 26400 | R7: 69600 | S7: 46247 | T7: 30
A8: GT-CHN-07 | B8: Slim Chino | C8: Bottoms | D8: Hemp-cotton blend | E8: OEKO-TEX | F8: Mekong Textile Co. | G8: Vietnam | H8: 60 | I8: 300 | J8: 26 | K8: 68 | L8: 42 | M8: 0.618 | N8: 20 | O8: N | P8: 0 | Q8: 0 | R8: 0 | U8: In GreenThreads catalog; stocked at other stores. Not in the Denver launch assortment.
A9: GT-JOG-03 | B9: Bamboo Joggers | C9: Bottoms | D9: Bamboo viscose | E9: OEKO-TEX | F9: Song Hong Apparel | G9: Vietnam | H9: 65 | I9: 250 | J9: 30 | K9: 78 | L9: 48 | M9: 0.615 | N9: 16 | O9: Y | P9: 950 | Q9: 28500 | R9: 74100 | S9: 46242 | T9: 25

Sheet Supplier Reliability
A1: Supplier Reliability — frequency, severity, and active exposure
A2: Frequency (% late) and severity (avg days late) are both reported because they answer different questions. Tier flags severity over 3 days.
A3: As_of_Date (drives overdue math): | D3: 46246
A5: Supplier | B5: Country | C5: Received | D5: Late (>0d) | E5: % Late | F5: Avg Days Late | G5: Max Days Late | H5: In Transit | I5: Overdue Now | J5: Tier
A6: Song Hong Apparel | B6: Vietnam | C6: =COUNTIFS('Shipments Data'!$D$2:$D$97,$A6,'Shipments Data'!$J$2:$J$97,"Received") -> 12 | D6: =COUNTIFS('Shipments Data'!$D$2:$D$97,$A6,'Shipments Data'!$J$2:$J$97,"Received",'Shipments Data'!$K$2:$K$97,">0") -> 12 | E6: =D6/C6 -> 1 | F6: =AVERAGEIFS('Shipments Data'!$K$2:$K$97,'Shipments Data'!$D$2:$D$97,$A6,'Shipments Data'!$J$2:$J$97,"Received") -> 12.083333 | G6: =MAXIFS('Shipments Data'!$K$2:$K$97,'Shipments Data'!$D$2:$D$97,$A6,'Shipments Data'!$J$2:$J$97,"Received") -> 19 | H6: =COUNTIFS('Shipments Data'!$D$2:$D$97,$A6,'Shipments Data'!$J$2:$J$97,"In transit") -> 3 | I6: =COUNTIFS('Shipments Data'!$D$2:$D$97,$A6,'Shipments Data'!$J$2:$J$97,"In transit",'Shipments Data'!$H$2:$H$97,"<"&$D$3) -> 2 | J6: =IF(F6>3,"At risk","Reliable") -> At risk
A7: Mekong Textile Co. | B7: Vietnam | C7: =COUNTIFS('Shipments Data'!$D$2:$D$97,$A7,'Shipments Data'!$J$2:$J$97,"Received") -> 17 | D7: =COUNTIFS('Shipments Data'!$D$2:$D$97,$A7,'Shipments Data'!$J$2:$J$97,"Received",'Shipments Data'!$K$2:$K$97,">0") -> 17 | E7: =D7/C7 -> 1 | F7: =AVERAGEIFS('Shipments Data'!$K$2:$K$97,'Shipments Data'!$D$2:$D$97,$A7,'Shipments Data'!$J$2:$J$97,"Received") -> 6.9411765 | G7: =MAXIFS('Shipments Data'!$K$2:$K$97,'Shipments Data'!$D$2:$D$97,$A7,'Shipments Data'!$J$2:$J$97,"Received") -> 12 | H7: =COUNTIFS('Shipments Data'!$D$2:$D$97,$A7,'Shipments Data'!$J$2:$J$97,"In transit") -> 9 | I7: =COUNTIFS('Shipments Data'!$D$2:$D$97,$A7,'Shipments Data'!$J$2:$J$97,"In transit",'Shipments Data'!$H$2:$H$97,"<"&$D$3) -> 9 | J7: =IF(F7>3,"At risk","Reliable") -> At risk
A8: Delta Organics | B8: India | C8: =COUNTIFS('Shipments Data'!$D$2:$D$97,$A8,'Shipments Data'!$J$2:$J$97,"Received") -> 28 | D8: =COUNTIFS('Shipments Data'!$D$2:$D$97,$A8,'Shipments Data'!$J$2:$J$97,"Received",'Shipments Data'!$K$2:$K$97,">0") -> 16 | E8: =D8/C8 -> 0.57142857 | F8: =AVERAGEIFS('Shipments Data'!$K$2:$K$97,'Shipments Data'!$D$2:$D$97,$A8,'Shipments Data'!$J$2:$J$97,"Received") -> 0.75 | G8: =MAXIFS('Shipments Data'!$K$2:$K$97,'Shipments Data'!$D$2:$D$97,$A8,'Shipments Data'!$J$2:$J$97,"Received") -> 2 | H8: =COUNTIFS('Shipments Data'!$D$2:$D$97,$A8,'Shipments Data'!$J$2:$J$97,"In transit") -> 4 | I8: =COUNTIFS('Shipments Data'!$D$2:$D$97,$A8,'Shipments Data'!$J$2:$J$97,"In transit",'Shipments Data'!$H$2:$H$97,"<"&$D$3) -> 4 | J8: =IF(F8>3,"At risk","Reliable") -> Reliable
A9: Andes Knitworks | B9: Colombia | C9: =COUNTIFS('Shipments Data'!$D$2:$D$97,$A9,'Shipments Data'!$J$2:$J$97,"Received") -> 23 | D9: =COUNTIFS('Shipments Data'!$D$2:$D$97,$A9,'Shipments Data'!$J$2:$J$97,"Received",'Shipments Data'!$K$2:$K$97,">0") -> 12 | E9: =D9/C9 -> 0.52173913 | F9: =AVERAGEIFS('Shipments Data'!$K$2:$K$97,'Shipments Data'!$D$2:$D$97,$A9,'Shipments Data'!$J$2:$J$97,"Received") -> 0.52173913 | G9: =MAXIFS('Shipments Data'!$K$2:$K$97,'Shipments Data'!$D$2:$D$97,$A9,'Shipments Data'!$J$2:$J$97,"Received") -> 1 | H9: =COUNTIFS('Shipments Data'!$D$2:$D$97,$A9,'Shipments Data'!$J$2:$J$97,"In transit") -> 0 | I9: =COUNTIFS('Shipments Data'!$D$2:$D$97,$A9,'Shipments Data'!$J$2:$J$97,"In transit",'Shipments Data'!$H$2:$H$97,"<"&$D$3) -> 0 | J9: =IF(F9>3,"At risk","Reliable") -> Reliable
A11: Both Vietnam suppliers are late on 100% of completed orders. Mekong ties Song Hong on frequency across a larger base and has more overdue orders in transit right now; Song Hong is worse on severity.

Sheet Launch Risk
A1: Denver Launch Risk (opening October 12, 2026)
A2: Four launch SKUs mapped to supplier severity. Retail value is the exposure a delay puts in play; carton status flags receiving risk.
A4: SKU | B4: Product | C4: Supplier | D4: Units | E4: Unit Cost | F4: Opening Buy Cost | G4: MSRP | H4: Retail Value | I4: Avg Days Late | J4: Units/Carton | K4: Cartons | L4: Tier | M4: Retail at Risk
A5: GT-HOD-04 | B5: EcoFleece Hoodie | C5: Andes Knitworks | D5: 850 | E5: 38 | F5: =D5*E5 -> 32300 | G5: 98 | H5: =D5*G5 -> 83300 | I5: {=INDEX('Supplier Reliability'!$F$6:$F$9,MATCH(C5,'Supplier Reliability'!$A$6:$A$9,0))} -> 0.52173913 | J5: 12 | K5: =IF(MOD(D5,J5)=0,"Whole","Partial") -> Partial | L5: {=INDEX('Supplier Reliability'!$J$6:$J$9,MATCH(C5,'Supplier Reliability'!$A$6:$A$9,0))} -> Reliable | M5: =IF(L5="At risk",H5,0) -> 0
A6: GT-TEE-01 | B6: Classic Tee | C6: Delta Organics | D6: 1600 | E6: 14.25 | F6: =D6*E6 -> 22800 | G6: 38 | H6: =D6*G6 -> 60800 | I6: {=INDEX('Supplier Reliability'!$F$6:$F$9,MATCH(C6,'Supplier Reliability'!$A$6:$A$9,0))} -> 0.75 | J6: 24 | K6: =IF(MOD(D6,J6)=0,"Whole","Partial") -> Partial | L6: {=INDEX('Supplier Reliability'!$J$6:$J$9,MATCH(C6,'Supplier Reliability'!$A$6:$A$9,0))} -> Reliable | M6: =IF(L6="At risk",H6,0) -> 0
A7: GT-SHT-02 | B7: Active Shorts | C7: Mekong Textile Co. | D7: 1200 | E7: 22 | F7: =D7*E7 -> 26400 | G7: 58 | H7: =D7*G7 -> 69600 | I7: {=INDEX('Supplier Reliability'!$F$6:$F$9,MATCH(C7,'Supplier Reliability'!$A$6:$A$9,0))} -> 6.9411765 | J7: 20 | K7: =IF(MOD(D7,J7)=0,"Whole","Partial") -> Whole | L7: {=INDEX('Supplier Reliability'!$J$6:$J$9,MATCH(C7,'Supplier Reliability'!$A$6:$A$9,0))} -> At risk | M7: =IF(L7="At risk",H7,0) -> 69600
A8: GT-JOG-03 | B8: Bamboo Joggers | C8: Song Hong Apparel | D8: 950 | E8: 30 | F8: =D8*E8 -> 28500 | G8: 78 | H8: =D8*G8 -> 74100 | I8: {=INDEX('Supplier Reliability'!$F$6:$F$9,MATCH(C8,'Supplier Reliability'!$A$6:$A$9,0))} -> 12.083333 | J8: 16 | K8: =IF(MOD(D8,J8)=0,"Whole","Partial") -> Partial | L8: {=INDEX('Supplier Reliability'!$J$6:$J$9,MATCH(C8,'Supplier Reliability'!$A$6:$A$9,0))} -> At risk | M8: =IF(L8="At risk",H8,0) -> 74100
C9: TOTAL | D9: =SUM(D5:D8) -> 4600 | F9: =SUM(F5:F8) -> 110000 | H9: =SUM(H5:H8) -> 287800 | M9: =SUM(M5:M8) -> 143700
A10: Share of launch retail value at risk: | M10: =M9/H9 -> 0.49930507
A12: Planning inference, not a forecast: applying Song Hong's 12.1-day historical mean to SH-2291's October 3 promise implies roughly an October 15 receipt, three days after opening.

Sheet Choice Set
A1: Choice Set & Recommendation
A3: Assumptions (yellow = estimate or judgment, not measured in the data)
A4: Opening day | B4: October 12, 2026 — derived: every launch SKU's Order_By_Date + Lead_Time_Days
A5: As_of_Date | B5: August 12, 2026 — drives all overdue and elapsed calculations
A6: Realistic slip | B6: Song Hong ~12 days, Mekong ~7 days, from their own completed-order history
A7: Freight and duty | B7: Wholesale cost is merchandise only; true landed COGS is higher, so margin shown is gross of freight and duty
A8: Expedite cost | B8: Quote-based; no freight or lost-sales figure is invented in this analysis
A10: Options
A11: Option | B11: Operating move | C11: Value | D11: Trade-off / limitation | E11: Position
A12: A. Observe | B12: Rely on promised dates and routine monitoring; no change. | C12: No new process or spend. | D12: No control at all for two suppliers with 100% late histories. | E12: Reject
A13: B. Control | B13: Require ex-factory, container-load, booking, and weekly milestones on both Vietnam launch POs; test the SOP two-week buffer. | C13: Earlier visibility and supplier accountability at no freight cost. | D13: Monitoring alone creates no backup if a milestone actually slips. | E13: Partial
A14: C. Gate (recommended) | B14: Adopt B, secure partial-expedite and backup-source quotes now, and release spend only on a verified trigger. Adopt a standing rule: any supplier averaging over 3 days late gets an automatic two-week buffer and expedite review. | C14: Preserves action time, keeps the decision evidence-based, and prevents the same failure on the next launch. | D14: Requires cross-functional coordination; final cost stays quote-based until a trigger fires. | E14: APPROVE
A16: Recommendation: Approve Option C. It targets the two suppliers with verified 100% late rates, avoids paying to rush units that would sell weeks after opening, and converts a one-time save into a standing rule tied to the HW#1 goal of an on-time Denver opening. Operations places both Vietnam launch items on exception control; Procurement obtains quotes and approves any spend or sourcing change; Legal owns contract terms.
